{"uuid": "729a6918-2e96-4f9a-be82-0aa4e4ffa731", "children": ["0470907a-0ca2-4cdf-9989-ac84f93b6524"], "befores": [{"name": "common_driver", "status": "broken", "statusDetails": {"message": "selenium.common.exceptions.WebDriverException: Message: An unknown server-side error occurred while processing the command. Original error: Error getting device API level. Original error: Error executing adbExec. Original error: 'Command '/Users/tangyao/Android/sdk/platform-tools/adb -P 5037 -s emulator-5554 shell getprop ro.build.version.sdk' exited with code 1'; Stderr: 'error: device offline'; Code: '1'\n\n", "trace": "  File \"/usr/local/lib/python3.7/site-packages/pluggy/callers.py\", line 187, in _multicall\n    res = hook_impl.function(*args)\n  File \"/usr/local/lib/python3.7/site-packages/_pytest/fixtures.py\", line 958, in pytest_fixture_setup\n    result = call_fixture_func(fixturefunc, request, kwargs)\n  File \"/usr/local/lib/python3.7/site-packages/_pytest/fixtures.py\", line 784, in call_fixture_func\n    res = next(it)\n  File \"/Users/tangyao/PycharmProjects/AppiumTest/conftest.py\", line 26, in common_driver\n    driver=base_driver.get_driver()\n  File \"/Users/tangyao/PycharmProjects/AppiumTest/config/driver_config.py\", line 60, in get_driver\n    raise e\n  File \"/Users/tangyao/PycharmProjects/AppiumTest/config/driver_config.py\", line 53, in get_driver\n    driver=webdriver.Remote(\"http://localhost:{0}/wd/hub\".format(str(self.device_info['serverPort'])), caps)\n  File \"/usr/local/lib/python3.7/site-packages/appium/webdriver/webdriver.py\", line 151, in __init__\n    proxy\n  File \"/usr/local/lib/python3.7/site-packages/selenium/webdriver/remote/webdriver.py\", line 157, in __init__\n    self.start_session(capabilities, browser_profile)\n  File \"/usr/local/lib/python3.7/site-packages/appium/webdriver/webdriver.py\", line 227, in start_session\n    response = self.execute(RemoteCommand.NEW_SESSION, parameters)\n  File \"/usr/local/lib/python3.7/site-packages/selenium/webdriver/remote/webdriver.py\", line 321, in execute\n    self.error_handler.check_response(response)\n  File \"/usr/local/lib/python3.7/site-packages/selenium/webdriver/remote/errorhandler.py\", line 242, in check_response\n    raise exception_class(message, screen, stacktrace)\n"}, "start": 1589903111488, "stop": 1589903140324}], "start": 1589903111488, "stop": 1589903140533}