{"uuid": "a7637536-18b9-447b-ac8a-e0c06c04f33b", "children": ["00512656-2e86-4a2f-9fb3-ca0bf8f30692"], "befores": [{"name": "common_driver", "status": "broken", "statusDetails": {"message": "urllib3.exceptions.MaxRetryError: HTTPConnectionPool(host='localhost', port=4725): Max retries exceeded with url: /wd/hub/session (Caused by NewConnectionError('<urllib3.connection.HTTPConnection object at 0x10de89790>: Failed to establish a new connection: [Errno 61] Connection refused'))\n", "trace": "  File \"/usr/local/lib/python3.7/site-packages/pluggy/callers.py\", line 187, in _multicall\n    res = hook_impl.function(*args)\n  File \"/usr/local/lib/python3.7/site-packages/_pytest/fixtures.py\", line 958, in pytest_fixture_setup\n    result = call_fixture_func(fixturefunc, request, kwargs)\n  File \"/usr/local/lib/python3.7/site-packages/_pytest/fixtures.py\", line 784, in call_fixture_func\n    res = next(it)\n  File \"/Users/tangyao/PycharmProjects/AppiumTest/conftest.py\", line 26, in common_driver\n    driver=base_driver.get_driver()\n  File \"/Users/tangyao/PycharmProjects/AppiumTest/config/driver_config.py\", line 60, in get_driver\n    raise e\n  File \"/Users/tangyao/PycharmProjects/AppiumTest/config/driver_config.py\", line 53, in get_driver\n    driver=webdriver.Remote(\"http://localhost:{0}/wd/hub\".format(str(self.device_info['serverPort'])), caps)\n  File \"/usr/local/lib/python3.7/site-packages/appium/webdriver/webdriver.py\", line 151, in __init__\n    proxy\n  File \"/usr/local/lib/python3.7/site-packages/selenium/webdriver/remote/webdriver.py\", line 157, in __init__\n    self.start_session(capabilities, browser_profile)\n  File \"/usr/local/lib/python3.7/site-packages/appium/webdriver/webdriver.py\", line 227, in start_session\n    response = self.execute(RemoteCommand.NEW_SESSION, parameters)\n  File \"/usr/local/lib/python3.7/site-packages/selenium/webdriver/remote/webdriver.py\", line 319, in execute\n    response = self.command_executor.execute(driver_command, params)\n  File \"/usr/local/lib/python3.7/site-packages/selenium/webdriver/remote/remote_connection.py\", line 374, in execute\n    return self._request(command_info[0], url, body=data)\n  File \"/usr/local/lib/python3.7/site-packages/selenium/webdriver/remote/remote_connection.py\", line 397, in _request\n    resp = self._conn.request(method, url, body=body, headers=headers)\n  File \"/usr/local/lib/python3.7/site-packages/urllib3/request.py\", line 80, in request\n    method, url, fields=fields, headers=headers, **urlopen_kw\n  File \"/usr/local/lib/python3.7/site-packages/urllib3/request.py\", line 171, in request_encode_body\n    return self.urlopen(method, url, **extra_kw)\n  File \"/usr/local/lib/python3.7/site-packages/urllib3/poolmanager.py\", line 330, in urlopen\n    response = conn.urlopen(method, u.request_uri, **kw)\n  File \"/usr/local/lib/python3.7/site-packages/urllib3/connectionpool.py\", line 760, in urlopen\n    **response_kw\n  File \"/usr/local/lib/python3.7/site-packages/urllib3/connectionpool.py\", line 760, in urlopen\n    **response_kw\n  File \"/usr/local/lib/python3.7/site-packages/urllib3/connectionpool.py\", line 760, in urlopen\n    **response_kw\n  File \"/usr/local/lib/python3.7/site-packages/urllib3/connectionpool.py\", line 720, in urlopen\n    method, url, error=e, _pool=self, _stacktrace=sys.exc_info()[2]\n  File \"/usr/local/lib/python3.7/site-packages/urllib3/util/retry.py\", line 436, in increment\n    raise MaxRetryError(_pool, url, error or ResponseError(cause))\n"}, "start": 1589902958099, "stop": 1589902958189}], "start": 1589902958099, "stop": 1589902959221}